#!/usr/bin/env python
# -*- coding: utf-8 -*-

from setuptools import setup
import upy_error

version = upy_error.__version__

with open("README.md", "r", encoding="utf-8") as fh:
    long_description = fh.read()


setup(
    name="upy-error",
    version=version,
    author="Fernando Celmer",
    author_email="email@fernandocelmer.com",
    description="Python Trace Error",
    long_description=long_description,
    long_description_content_type="text/markdown",
    url="https://github.com/UpyExplorer/upy-error",
    packages=[
        'upy_error',
    ],
    include_package_data=True,
    classifiers=[
        "Operating System :: OS Independent",
        "License :: OSI Approved :: MIT License",
        'Intended Audience :: Developers',
        'Natural Language :: English',
        "Programming Language :: Python :: 3.6",
        "Programming Language :: Python :: 3.7",
        "Programming Language :: Python :: 3.8",
        "Programming Language :: Python :: 3.9",
        "Programming Language :: Python :: 3.10",
        "Programming Language :: Python :: 3.11",
    ],
    python_requires=">=3.6",
    zip_safe=False
)
